#user_defined_exception.py

